Workbook
Name SegmentaciónDeDatos_Actividad: #N/A
Name SegmentaciónDeDatos_Actividad1: #N/A
Name SegmentaciónDeDatos_Año: #N/A
Name SegmentaciónDeDatos_Año1: #N/A
Name SegmentaciónDeDatos_Estado: #N/A
Name SegmentaciónDeDatos_Estado1: #N/A
Name SegmentaciónDeDatos_Mes: #N/A
Name SegmentaciónDeDatos_Mes1: #N/A
Name SegmentaciónDeDatos_TAG: #N/A
Name SegmentaciónDeDatos_TAG1: #N/A

Sheet Hoja1

Sheet Hoja 1

Sheet Hoja2
G14: Condición | H14: Diámetro de boquilla (in) | I14: Caudal (MMSCFD) | J14: Velocidad (ft/s) | K14: Recomendado (ft/s) | L14: Cumple?
G15: Actual Entrada | H15: 6 | I15: 30 | J15: 54 | K15: 15-30 | L15: ❌ Alta
G16: Actual salida | H16: 4 | I16: 30 | J16: 123 | K16: 20-40 | L16: ❌ Alta
G17: Entrada proyectada | H17: 10 | I17: 30 | J17: 22.1 | K17: 15-30 | L17: ✅
G18: Salida proyectada | H18: 8 | I18: 30 | J18: 31.2 | K18: 20-40 | L18: ✅
H27: Entrada 6" | I27: 54
H28: Entrada 10" | I28: 22.1
H29: Salida 4" | I29: 123
H30: Saloida 8" | I30: 31.2

Sheet Calculos
B4: SELECT | C4: =+B8-2*L7 -> #N/A | D4: in
B5: Area | C5: =0.25*PI()*C4*C4/144 -> #N/A | D5: ft2
Q6: P | R6: 1480
L7: =+HLOOKUP(Hoja1!H15,D8:K26,L8,FALSE) -> #N/A | Q7: D | R7: 10
B8: =+VLOOKUP(Hoja1!H14,B9:C26,2,FALSE) -> #N/A | C8: DIAM EXT | D8: SCH 10 | E8: SCH 20 | F8: SCH 30 | G8: STD | H8: SCH 40 | I8: SCH 60 | J8: XS | K8: SCH 80 | L8: =1+VLOOKUP(Hoja1!H14,B9:L26,11,FALSE) -> #N/A | Q8: S | R8: 35000
A9: =+L9 -> 1 | B9: 1 | C9: 1.315 | G9: 0.133 | H9: 0.133 | J9: 0.179 | K9: 0.179 | L9: 1 | Q9: F | R9: 0.5
A10: =+L10 -> 2 | B10: 2 | C10: 2.375 | G10: 0.154 | H10: 0.154 | J10: 0.218 | K10: 0.218 | L10: 2 | Q10: E | R10: 1
A11: =+L11 -> 3 | B11: 3 | C11: 3.5 | G11: 0.126 | H11: 0.216 | J11: 0.3 | K11: 0.3 | L11: 3 | Q11: T | R11: 1
A12: =+L12 -> 4 | B12: 4 | C12: 4.5 | G12: 0.237 | H12: 0.237 | J12: 0.337 | K12: 0.337 | L12: 4
A13: =+L13 -> 5 | B13: 6 | C13: 6.625 | G13: 0.28 | H13: 0.28 | J13: 0.432 | K13: 0.432 | L13: 5
A14: =+L14 -> 6 | B14: 8 | C14: 8.625 | E14: 0.25 | F14: 0.277 | G14: 0.322 | H14: 0.322 | I14: 0.406 | J14: 0.5 | K14: 0.5 | L14: 6
A15: =+L15 -> 7 | B15: 10 | C15: 10.75 | E15: 0.25 | F15: 0.307 | G15: 0.365 | H15: 0.365 | I15: 0.5 | J15: 0.5 | K15: 0.594 | L15: 7
A16: =+L16 -> 8 | B16: 12 | C16: 12.75 | E16: 0.25 | F16: 0.33 | G16: 0.375 | H16: 0.406 | I16: 0.562 | J16: 0.5 | K16: 0.688 | L16: 8 | Q16: t | R16: =+(R6*R7)/(2*R8*R9*R10*R11) -> 0.42285714
A17: =+L17 -> 9 | B17: 14 | C17: 14 | D17: 0.25 | E17: 0.312 | F17: 0.375 | G17: 0.375 | H17: 0.438 | I17: 0.594 | J17: 0.5 | K17: 0.75 | L17: 9
A18: =+L18 -> 10 | B18: 16 | C18: 16 | D18: 0.25 | E18: 0.312 | F18: 0.375 | G18: 0.375 | H18: 0.5 | I18: 0.656 | J18: 0.5 | K18: 0.844 | L18: 10 | Q18: A | R18: =0.25*(PI()*(R7-2*R16)^2)/144 -> 0.45706326 | S18: ft
A19: =+L19 -> 11 | B19: 18 | C19: 18 | D19: 0.25 | E19: 0.312 | F19: 0.438 | G19: 0.375 | H19: 0.562 | I19: 0.75 | J19: 0.5 | K19: 0.938 | L19: 11
A20: =+L20 -> 12 | B20: 20 | C20: 20 | D20: 0.25 | E20: 0.375 | F20: 0.5 | G20: 0.375 | H20: 0.594 | I20: 0.812 | J20: 0.5 | K20: 1.031 | L20: 12 | Q20: Qa | R20: =+R18*100 -> 45.706326
A21: =+L21 -> 13 | B21: 22 | C21: 22 | D21: 0.25 | E21: 0.375 | F21: 0.5 | G21: 0.375 | H21: 0 | I21: 0.875 | J21: 0.5 | K21: 1.125 | L21: 13
A22: =+L22 -> 14 | B22: 24 | C22: 24 | D22: 0.25 | E22: 0.375 | F22: 0.562 | G22: 0.375 | H22: 0.688 | I22: 0.969 | J22: 0.5 | K22: 1.219 | L22: 14 | Q22: Qs | R22: =+(R20*(R6+14.65)/14.65)*3600*24/1000000 -> 402.89506
A23: =+L23 -> 15 | B23: 26 | C23: 26 | D23: 0.312 | E23: 0.5 | F23: 0 | G23: 0.375 | J23: 0.5 | L23: 15
A24: =+L24 -> 16 | B24: 28 | C24: 28 | D24: 0.312 | E24: 0.5 | F24: 0.625 | G24: 0.375 | J24: 0.5 | L24: 16
A25: =+L25 -> 17 | B25: 30 | C25: 30 | D25: 0.312 | E25: 0.5 | F25: 0.625 | G25: 0.375 | J25: 0.5 | L25: 17
A26: =+L26 -> 18 | B26: 32 | C26: 32 | D26: 0.312 | E26: 0.5 | F26: 0.625 | G26: 0.375 | H26: 0.688 | J26: 0.5 | L26: 18
E36: =+HLOOKUP(Hoja1!H16,F36:L38,3,FALSE) -> #N/A | F36: 25 | G36: 50 | H36: 60 | I36: 80 | J36: 100 | K36: 120 | L36: 180 | M36: =+(M38*1000000)/24/3600/D46/$C$5 -> #N/A
E37: QA | F37: =+F36*$C$5 -> #N/A | G37: =+G36*$C$5 -> #N/A | H37: =+H36*$C$5 -> #N/A | I37: =+I36*$C$5 -> #N/A | J37: =+J36*$C$5 -> #N/A | K37: =+K36*$C$5 -> #N/A | L37: =+L36*$C$5 -> #N/A | M37: Ft3/seg
E38: QMMSCFD | F38: =+F37*$D$46*3600*24/1000000 -> #N/A | G38: =+G37*$D$46*3600*24/1000000 -> #N/A | H38: =+H37*$D$46*3600*24/1000000 -> #N/A | I38: =+I37*$D$46*3600*24/1000000 -> #N/A | J38: =+J37*$D$46*3600*24/1000000 -> #N/A | K38: =+K37*$D$46*3600*24/1000000 -> #N/A | L38: =+L37*$D$46*3600*24/1000000 -> #N/A | M38: =+Hoja1!H11 -> 0
C40: Fp | D40: =+(Hoja1!H12+14.65)/14.65 -> 1
C41: FT | D41: =+(60+460)/(Hoja1!H13+460) -> 1.1304348
C42: Zbase | D42: =1/(1+(14.65*344400*10^(1.785*Hoja1!H10))/((60+460)^3.825)) -> 0.99979389
C43: Zreal | D43: =1/(1+((Hoja1!H12+14.65)*344400*10^(1.785*Hoja1!H10))/((Hoja1!H13+460)^3.825)) -> 0.99967061
C44: FZ | D44: =+D42/D43 -> 1.0001233
C46: Fcorreccion | D46: =+D40*D41*D44 -> 1.1305742
B48: tamaño anterior | C48: =+VLOOKUP(L8-2,A9:B26,2,FALSE) -> #N/A
C49: =+VLOOKUP(C48,B9:C26,2,FALSE) -> #N/A | E49: =+HLOOKUP(Hoja1!H16,F49:L51,3,FALSE) -> #N/A | F49: 25 | G49: 50 | H49: 60 | I49: 80 | J49: 100 | K49: 120 | L49: 180 | M49: =+(M51*1000000)/24/3600/$D$46/$C$52 -> #N/A
C50: =+HLOOKUP(Hoja1!H15,D8:K26,L8-2,FALSE) -> #N/A | E50: QA | F50: =+F49*$C$52 -> #N/A | G50: =+G49*$C$52 -> #N/A | H50: =+H49*$C$52 -> #N/A | I50: =+I49*$C$52 -> #N/A | J50: =+J49*$C$52 -> #N/A | K50: =+K49*$C$52 -> #N/A | L50: =+L49*$C$52 -> #N/A | M50: Ft3/seg
B51: Din | C51: =+C49-2*C50 -> #N/A | E51: QMMSCFD | F51: =+F50*$D$46*3600*24/1000000 -> #N/A | G51: =+G50*$D$46*3600*24/1000000 -> #N/A | H51: =+H50*$D$46*3600*24/1000000 -> #N/A | I51: =+I50*$D$46*3600*24/1000000 -> #N/A | J51: =+J50*$D$46*3600*24/1000000 -> #N/A | K51: =+K50*$D$46*3600*24/1000000 -> #N/A | L51: =+L50*$D$46*3600*24/1000000 -> #N/A | M51: =+M38 -> 0
B52: Ain | C52: =0.25*PI()*C51*C51/144 -> #N/A | D52: ft2
B54: tamaño siguiente | C54: =+VLOOKUP(L8,A9:B26,2,FALSE) -> #N/A
C55: =+VLOOKUP(C54,B9:C26,2,FALSE) -> #N/A | E55: =+HLOOKUP(Hoja1!H16,F55:L57,3,FALSE) -> #N/A | F55: 25 | G55: 50 | H55: 60 | I55: 80 | J55: 100 | K55: 120 | L55: 180 | M55: =+(M57*1000000)/24/3600/$D$46/$C$58 -> #N/A
C56: =+HLOOKUP(Hoja1!H15,D8:K26,L8+1,FALSE) -> #N/A | E56: QA | F56: =+F55*$C$58 -> #N/A | G56: =+G55*$C$58 -> #N/A | H56: =+H55*$C$58 -> #N/A | I56: =+I55*$C$58 -> #N/A | J56: =+J55*$C$58 -> #N/A | K56: =+K55*$C$58 -> #N/A | L56: =+L55*$C$58 -> #N/A | M56: Ft3/seg
...

Sheet HeatExchanger
F2: MODELADOR HIDRAÚLICO PARA ESTIMAR LA CAPACIDAD DE FLUJO DE GAS NATURAL A TRAVÉS DE TUBERÍAS
AE4: =98-63 -> 35
C7: Datos de Proceso:
C9: Lado Tubos: | E9: Fluye Gas Caliente | P9: Lado Coraza: | R9: Fluye Gas Frio
C11: PARAMETRO | H11: VALOR | L11: UNIDAD | P11: PARAMETRO | U11: VALOR | Y11: UNIDAD
C12: Gravedad Específica del Gas: | H12: 0.5869 | L12: --- | P12: Gravedad Específica del Gas: | U12: 0.5869 | Y12: ---
C13: Flujo de Proceso: | H13: 30 | L13: MMSCFD | P13: Flujo de Proceso: | U13: 30 | Y13: MMSCFD
C14: Presión de Operación: | H14: 450 | L14: Psig | P14: Presión de Operación: | U14: 450 | Y14: Psig
C15: Temperatura Entrada: | H15: 68 | L15: °F | P15: Temperatura Entrada: | U15: 35 | Y15: °F
C16: Temperatura Salida (Diseño): | H16: 34 | L16: °F | P16: Temperatura Salida (Diseño): | U16: 65 | Y16: °F
C20: RESULTADOS | H20: VALOR | L20: UNIDAD | P20: RESULTADOS | U20: VALOR | Y20: UNIDAD
C21: Rata de Calor de Entrada | H21: =+Calculos!C96 -> 1005706.9 | L21: =+Calculos!D96 -> BTU/hr | P21: Rata de Calor de Entrada | U21: =+Calculos!F96 -> 887388.48 | Y21: =+Calculos!G96 -> BTU/hr
C22: Tamaño mínimo conexión IN | H22: =+Calculos!C129 -> 8.7435407 | L22: in | P22: Tamaño mínimo conexión IN | U22: =+Calculos!F129 -> 8.3905958 | Y22: in
C23: Tamaño mínimo conexión OUT | H23: =+Calculos!C130 -> 8.5971678 | L23: in | P23: Tamaño mínimo conexión OUT | U23: =+Calculos!F130 -> 8.9388233 | Y23: in
L24: in | Y24: in
C25: Tamaño recomendado conexión IN | H25: =+Calculos!C133 -> 10 | L25: in | P25: Tamaño recomendado conexión IN | U25: =+Calculos!F133 -> 10 | Y25: in
C26: Tamaño recomendado conexión OUT | H26: =+Calculos!C134 -> 10 | L26: in | P26: Tamaño recomendado conexión OUT | U26: =+Calculos!F134 -> 10 | Y26: in
C28: Temp de Salida Real Estimada | H28: =+Calculos!C98 -> 38 | L28: °F | P28: Temp de Salida Real Estimada | U28: =+Calculos!F98 -> 69 | Y28: °F
C36: Notas:
C48: Rev. | E48: Fecha | H48: Proyecto | O48: Cliente | R48: Elabora | U48: Revisa | X48: Aprueba

Sheet CANT MOVIMIENTO
F2: MODELADOR HIDRAÚLICO PARA ESTIMAR LA CAPACIDAD DE FLUJO DE GAS NATURAL A TRAVÉS DE TUBERÍAS
C7: Datos de Proceso:
C9: PARAMETRO | H9: VALOR | L9: UNIDAD
C10: Gravedad Específica del Gas: | H10: 0.5869 | L10: ---
C11: Flujo de Proceso: | H11: 30 | L11: MMSCFD
C12: Presión de Operación: | H12: 900 | L12: Psig
C13: Temperatura: | H13: 85 | L13: °F
C14: Diametro Evaluado: | H14: 10 | L14: In
C15: Espesor / Schedule: | H15: SCH 40 | L15: "
C16: Velocidad de diseño: | H16: 50 | L16: Ft/s
C18: RESULTADOS | H18: VALOR | L18: UNIDAD
C19: Factor Corrección Presión | H19: =+Calculos!D40 -> 1 | L19: ---
C20: Factor Corrección Temp | H20: =+Calculos!D41 -> 1.1304348 | L20: ---
C21: Factor Corrección Z | H21: =+Calculos!D44 -> 1.0001233 | L21: ---
C22: Capacidad Máx Recomendada: | H22: =+Calculos!E36 -> #N/A | L22: MMSCFD
C23: Velocidad Real @Proceso: | H23: =+Calculos!M36 -> #N/A | L23: Ft/s
C27: RESUMEN DE PROXIMIDAD
C29: EVALUACIÓN DE TAMAÑOS | H29: VALOR | L29: UNIDAD | N29: CAPACIDAD | R29: VELOCIDAD MÁX | V29: PORCENTAJE DE USO
C30: Diametro anterior | H30: =+Calculos!C48 -> #N/A | L30: In | N30: =+Calculos!E49 -> #N/A | P30: MMSCFD | R30: =+Calculos!M49 -> #N/A | T30: Ft/s | V30: =100*$H$11/N30 -> #N/A | X30: %
C31: Diametro Evaluado: | H31: =+H14 -> 10 | L31: In | N31: =+Calculos!E36 -> #N/A | P31: MMSCFD | R31: =+Calculos!M36 -> #N/A | T31: Ft/s | V31: =100*$H$11/N31 -> #N/A | X31: %
C32: Diametro siguiente | H32: =+Calculos!C54 -> #N/A | L32: In | N32: =+Calculos!E55 -> #N/A | P32: MMSCFD | R32: =+Calculos!M55 -> #N/A | T32: Ft/s | V32: =100*$H$11/N32 -> #N/A | X32: %
C46: Rev. | E46: Fecha | H46: Proyecto | O46: Cliente | R46: Elabora | U46: Revisa | X46: Aprueba
